Workbook

Sheet 科技表
A1: 科技ID | B1: 备注 | C1: 描述 | D1: 科技组 | E1: 科技等级 | F1: 最大升级等级 | G1: 种族 | H1: 科技类型 | I1: 科技子类型 | J1: 时间开销 | K1: 金币开销 | L1: 遣返金币 | M1: 解锁训练建造金币 | N1: 所需基地等级 | O1: 建造CD时间 | P1: 建造最大数量 | Q1: 建造初始血量百分比 | R1: 建造中护甲衰减万分比 | S1: 变身新单位ID | T1: 科技效果1类型 | U1: 科技效果1参数1 | V1: 科技效果1参数2 | W1: 科技效果1参数3 | X1: 科技效果1参数4 | Y1: 科技效果2类型 | Z1: 科技效果2参数1 | AA1: 科技效果2参数2 | AB1: 科技效果2参数3 | AC1: 科技效果2参数4 | AD1: 科技图标 | AE1: 科技名称_简中 | AF1: 科技名称_英文 | AG1: 科技名称_繁中 | AH1: 描述_简中 | AI1: 描述_英文 | AJ1: 描述_繁中 | AK1: 建造拖动特效 | AL1: 延时建造特效
A2: 10000001 | B2: 3v3升级一级基地 | D2: =LEFT(A2,6) -> 100000 | E2: =RIGHT(A2,1) -> 1 | F2: 1 | G2: 人族 | H2: 单位科技 | I2: 单位基地升级科技 | J2: 0 | K2: 0 | N2: 1 | T2: 科技效果_基地科技升级 | U2: 20000117 | Y2: 科技效果_提升最大人口 | Z2: 10 | AD2: UITexture/Charactar/renlei/hum_base01 | AE2: 一级城堡 | AF2: 一级城堡 | AG2: 一级城堡 | AH2: 可以升级至二级城堡，升级后可解锁中级兵种和中级科技，提升基地等级可提高基地和副基地、防御塔的战斗力，提升金矿防御力。保护基地不被摧毁对获得战争的胜利至关重要！ | AI2: Can be upgraded to level 2 castle, after upgrading intermediate Troops and Tech will be unlocked. It also increases combat effectiveness of base and secondary base. Protecting your base is vital to winning! | AJ2: 可以升级至二级城堡，升级后可解锁中级兵种和中级科技，提升基地等级可提高基地和副基地、防御塔的战斗力，提升金矿防御力。保护基地不被摧毁对获得战争的胜利至关重要！
A3: 10001001 | B3: 3v3升级二级基地 | D3: =LEFT(A3,6) -> 100010 | E3: =RIGHT(A3,1) -> 1 | F3: 1 | G3: 人族 | H3: 单位科技 | I3: 单位基地升级科技 | J3: 75000 | K3: 1000 | N3: 1 | T3: 科技效果_基地科技升级 | U3: 20000118 | AD3: UITexture/Charactar/renlei/hum_base02 | AE3: 二级城堡 | AF3: 二级城堡 | AG3: 二级城堡 | AH3: 可以升级至三级城堡，升级后可解锁高级兵种和高级科技，可提高基地和副基地、防御塔的战斗力，提升金矿防御力。保护基地不被摧毁对获得战争的胜利至关重要！ | AI3: Can be upgraded to level 3 castle. After upgrading, advanced Troops and Tech will be unlocked. It also increases combat effectiveness of base and secondary base. Protecting your base is vital to winning! | AJ3: 可以升级至三级城堡，升级后可解锁高级兵种和高级科技，可提高基地和副基地、防御塔的战斗力，提升金矿防御力。保护基地不被摧毁对获得战争的胜利至关重要！
A4: 10002001 | B4: 3v3升级三级基地 | D4: =LEFT(A4,6) -> 100020 | E4: =RIGHT(A4,1) -> 1 | F4: 1 | G4: 人族 | H4: 单位科技 | I4: 单位基地升级科技 | J4: 90000 | K4: 1000 | N4: 2 | T4: 科技效果_基地科技升级 | U4: 20000119 | AD4: UITexture/Charactar/renlei/hum_base03 | AE4: 三级城堡 | AF4: 三级城堡 | AG4: 三级城堡 | AH4: 可训练高级兵种和研究高级科技，可提高基地和副基地、防御塔的战斗力，提升金矿防御力。保护基地不被摧毁对获得战争的胜利至关重要！ | AI4: Can train high level Troops and research high level Tech. It also increases combat effectiveness of base and secondary base. Protecting your base is vital to winning! | AJ4: 可训练高级兵种和研究高级科技，可提高基地和副基地、防御塔的战斗力，提升金矿防御力。保护基地不被摧毁对获得战争的胜利至关重要！
A5: 10003001 | B5: 1v1人口升级1 | D5: =LEFT(A5,6) -> 100030 | E5: =RIGHT(A5,1) -> 1 | F5: 4 | G5: 人族 | H5: 团队科技 | I5: 团队人口升级科技 | J5: 20000 | K5: 250 | N5: 1 | T5: 科技效果_提升最大人口 | U5: 5 | AD5: UITexture/Charactar/keji/food_1 | AE5: 人口升级 | AF5: 人口升级 | AG5: 人口升级 | AH5: 研究后增加5人口。 | AI5: Increases Supply Cap by 5 | AJ5: 研究后增加5人口。
A6: 10003002 | B6: 1v1人口升级2 | D6: =LEFT(A6,6) -> 100030 | E6: =RIGHT(A6,1) -> 2 | F6: 4 | G6: 人族 | H6: 团队科技 | I6: 团队人口升级科技 | J6: 20000 | K6: 250 | N6: 1 | T6: 科技效果_提升最大人口 | U6: 5 | AD6: UITexture/Charactar/keji/food_1 | AE6: 人口升级 | AF6: 人口升级 | AG6: 人口升级 | AH6: 研究后增加5人口。 | AI6: Increases Supply Cap by 5 | AJ6: 研究后增加5人口。
A7: 10003003 | B7: 1v1人口升级3 | D7: =LEFT(A7,6) -> 100030 | E7: =RIGHT(A7,1) -> 3 | F7: 4 | G7: 人族 | H7: 团队科技 | I7: 团队人口升级科技 | J7: 20000 | K7: 250 | N7: 1 | T7: 科技效果_提升最大人口 | U7: 5 | AD7: UITexture/Charactar/keji/food_1 | AE7: 人口升级 | AF7: 人口升级 | AG7: 人口升级 | AH7: 研究后增加5人口。 | AI7: Increases Supply Cap by 5 | AJ7: 研究后增加5人口。
A8: 10003004 | B8: 1v1人口升级4 | D8: =LEFT(A8,6) -> 100030 | E8: =RIGHT(A8,1) -> 4 | F8: 4 | G8: 人族 | H8: 团队科技 | I8: 团队人口升级科技 | J8: 20000 | K8: 250 | N8: 1 | T8: 科技效果_提升最大人口 | U8: 5 | AD8: UITexture/Charactar/keji/food_1 | AE8: 人口升级 | AF8: 人口升级 | AG8: 人口升级 | AH8: 研究后增加5人口。 | AI8: Increases Supply Cap by 5 | AJ8: 研究后增加5人口。
A9: 10004001 | B9: 攻击升级1 | D9: =LEFT(A9,6) -> 100040 | E9: =RIGHT(A9,1) -> 1 | F9: 3 | G9: 人族 | H9: 团队科技 | I9: 团队攻击升级科技 | J9: 30000 | K9: 250 | N9: 1 | T9: 科技效果_提升单位攻防属性 | U9: 攻击力 | AD9: UITexture/Charactar/keji/hum_tech_attack1 | AE9: 初级攻击 | AF9: 初级攻击 | AG9: 初级攻击 | AH9: 研究后增加士兵攻击力。@矮人步兵\n\n弩手\n\n矮人直升机\n\n魔法守卫\n\n鹰骑士\n\n骑士\n\n炮车\n\n龙骑士@130 <color=#00ff00>+13</color>\n\n230 <color=#00ff00>+23</color>\n\n180 <color=#00ff00>+18</color>\n\n190 <color=#00ff00>+19</color>\n\n230 <color=#00ff00>+23</color>\n\n300 <color=#00ff00>+30</color>\n\n520 <color=#00ff00>+52</color>\n\n400 <color=#00ff00>+40</color> | AI9: Increases troop damage。@Dwarf Infantry\n\nCrossbowman\n\nDwarf Bomber\n\nMagic Guard\n\nEagle Rider\n\nHeavy Knight\n\nCannon\n\nDragon Knight@130 <color=#00ff00>+13</color>\n\n230 <color=#00ff00>+23</color>\n\n180 <color=#00ff00>+18</color>\n\n190 <color=#00ff00>+19</color>\n\n230 <color=#00ff00>+23</color>\n\n300 <color=#00ff00>+30</color>\n\n520 <color=#00ff00>+52</color>\n\n400 <color=#00ff00>+40</color> | AJ9: 研究后增加士兵攻击力。@矮人步兵\n\n弩手\n\n矮人直升机\n\n魔法守卫\n\n鹰骑士\n\n骑士\n\n炮车\n\n龙骑士@130 <color=#00ff00>+13</color>\n\n230 <color=#00ff00>+23</color>\n\n180 <color=#00ff00>+18</color>\n\n190 <color=#00ff00>+19</color>\n\n230 <color=#00ff00>+23</color>\n\n300 <color=#00ff00>+30</color>\n\n520 <color=#00ff00>+52</color>\n\n400 <color=#00ff00>+40</color>
A10: 10004002 | B10: 攻击升级2 | D10: =LEFT(A10,6) -> 100040 | E10: =RIGHT(A10,1) -> 2 | F10: 3 | G10: 人族 | H10: 团队科技 | I10: 团队攻击升级科技 | J10: 45000 | K10: 500 | N10: 2 | T10: 科技效果_提升单位攻防属性 | U10: 攻击力 | AD10: UITexture/Charactar/keji/hum_tech_attack2 | AE10: 中级攻击 | AF10: 中级攻击 | AG10: 中级攻击 | AH10: 研究后增加士兵攻击力。@矮人步兵\n\n弩手\n\n矮人直升机\n\n魔法守卫\n\n鹰骑士\n\n骑士\n\n炮车\n\n龙骑士@143 <color=#00ff00>+13</color>\n\n253 <color=#00ff00>+23</color>\n\n198 <color=#00ff00>+18</color>\n\n209 <color=#00ff00>+19</color>\n\n253 <color=#00ff00>+23</color>\n\n330 <color=#00ff00>+30</color>\n\n572 <color=#00ff00>+52</color>\n\n440 <color=#00ff00>+40</color> | AI10: Increases troop damage。@Dwarf Infantry\n\nCrossbowman\n\nDwarf Bomber\n\nMagic Guard\n\nEagle Rider\n\nHeavy Knight\n\nCannon\n\nDragon Knight@143 <color=#00ff00>+13</color>\n\n253 <color=#00ff00>+23</color>\n\n198 <color=#00ff00>+18</color>\n\n209 <color=#00ff00>+19</color>\n\n253 <color=#00ff00>+23</color>\n\n330 <color=#00ff00>+30</color>\n\n572 <color=#00ff00>+52</color>\n\n440 <color=#00ff00>+40</color> | AJ10: 研究后增加士兵攻击力。@矮人步兵\n\n弩手\n\n矮人直升机\n\n魔法守卫\n\n鹰骑士\n\n骑士\n\n炮车\n\n龙骑士@143 <color=#00ff00>+13</color>\n\n253 <color=#00ff00>+23</color>\n\n198 <color=#00ff00>+18</color>\n\n209 <color=#00ff00>+19</color>\n\n253 <color=#00ff00>+23</color>\n\n330 <color=#00ff00>+30</color>\n\n572 <color=#00ff00>+52</color>\n\n440 <color=#00ff00>+40</color>
A11: 10004003 | B11: 攻击升级3 | D11: =LEFT(A11,6) -> 100040 | E11: =RIGHT(A11,1) -> 3 | F11: 3 | G11: 人族 | H11: 团队科技 | I11: 团队攻击升级科技 | J11: 60000 | K11: 800 | N11: 3 | T11: 科技效果_提升单位攻防属性 | U11: 攻击力 | AD11: UITexture/Charactar/keji/hum_tech_attack3 | AE11: 高级攻击 | AF11: 高级攻击 | AG11: 高级攻击 | AH11: 研究后增加士兵攻击力。@矮人步兵\n\n弩手\n\n矮人直升机\n\n魔法守卫\n\n鹰骑士\n\n骑士\n\n炮车\n\n龙骑士@156 <color=#00ff00>+13</color>\n\n276 <color=#00ff00>+23</color>\n\n216 <color=#00ff00>+18</color>\n\n228 <color=#00ff00>+19</color>\n\n276 <color=#00ff00>+23</color>\n\n360 <color=#00ff00>+30</color>\n\n624 <color=#00ff00>+52</color>\n\n480 <color=#00ff00>+40</color> | AI11: Increases troop damage。@Dwarf Infantry\n\nCrossbowman\n\nDwarf Bomber\n\nMagic Guard\n\nEagle Rider\n\nHeavy Knight\n\nCannon\n\nDragon Knight@156 <color=#00ff00>+13</color>\n\n276 <color=#00ff00>+23</color>\n\n216 <color=#00ff00>+18</color>\n\n228 <color=#00ff00>+19</color>\n\n276 <color=#00ff00>+23</color>\n\n360 <color=#00ff00>+30</color>\n\n624 <color=#00ff00>+52</color>\n\n480 <color=#00ff00>+40</color> | AJ11: 研究后增加士兵攻击力。@矮人步兵\n\n弩手\n\n矮人直升机\n\n魔法守卫\n\n鹰骑士\n\n骑士\n\n炮车\n\n龙骑士@156 <color=#00ff00>+13</color>\n\n276 <color=#00ff00>+23</color>\n\n216 <color=#00ff00>+18</color>\n\n228 <color=#00ff00>+19</color>\n\n276 <color=#00ff00>+23</color>\n\n360 <color=#00ff00>+30</color>\n\n624 <color=#00ff00>+52</color>\n\n480 <color=#00ff00>+40</color>
A12: 10005001 | B12: 防御升级1 | D12: =LEFT(A12,6) -> 100050 | E12: =RIGHT(A12,1) -> 1 | F12: 3 | G12: 人族 | H12: 团队科技 | I12: 团队防御升级科技 | J12: 30000 | K12: 250 | N12: 1 | T12: 科技效果_提升单位攻防属性 | U12: 护甲值 | AD12: UITexture/Charactar/keji/hum_tech_defence1 | AE12: 初级防御 | AF12: 初级防御 | AG12: 初级防御 | AH12: 研究后增加士兵防御力。@矮人步兵\n\n弩手\n\n矮人直升机\n\n魔法守卫\n\n鹰骑士\n\n骑士\n\n炮车\n\n龙骑士@72 <color=#00ff00>+72</color>\n\n0 <color=#00ff00>+72</color>\n\n72 <color=#00ff00>+72</color>\n\n108 <color=#00ff00>+72</color>\n\n36 <color=#00ff00>+72</color>\n\n180 <color=#00ff00>+72</color>\n\n72 <color=#00ff00>+72</color>\n\n0 <color=#00ff00>+72</color> | AI12: Increases troop defense。@Dwarf Infantry\n\nCrossbowman\n\nDwarf Bomber\n\nMagic Guard\n\nEagle Rider\n\nHeavy Knight\n\nCannon\n\nDragon Knight@72 <color=#00ff00>+72</color>\n\n0 <color=#00ff00>+72</color>\n\n72 <color=#00ff00>+72</color>\n\n108 <color=#00ff00>+72</color>\n\n36 <color=#00ff00>+72</color>\n\n180 <color=#00ff00>+72</color>\n\n72 <color=#00ff00>+72</color>\n\n0 <color=#00ff00>+72</color> | AJ12: 研究后增加士兵防御力。@矮人步兵\n\n弩手\n\n矮人直升机\n\n魔法守卫\n\n鹰骑士\n\n骑士\n\n炮车\n\n龙骑士@72 <color=#00ff00>+72</color>\n\n0 <color=#00ff00>+72</color>\n\n72 <color=#00ff00>+72</color>\n\n108 <color=#00ff00>+72</color>\n\n36 <color=#00ff00>+72</color>\n\n180 <color=#00ff00>+72</color>\n\n72 <color=#00ff00>+72</color>\n\n0 <color=#00ff00>+72</color>
A13: 10005002 | B13: 防御升级2 | D13: =LEFT(A13,6) -> 100050 | E13: =RIGHT(A13,1) -> 2 | F13: 3 | G13: 人族 | H13: 团队科技 | I13: 团队防御升级科技 | J13: 45000 | K13: 500 | N13: 2 | T13: 科技效果_提升单位攻防属性 | U13: 护甲值 | AD13: UITexture/Charactar/keji/hum_tech_defence2 | AE13: 中级防御 | AF13: 中级防御 | AG13: 中级防御 | AH13: 研究后增加士兵防御力。@矮人步兵\n\n弩手\n\n矮人直升机\n\n魔法守卫\n\n鹰骑士\n\n骑士\n\n炮车\n\n龙骑士@144 <color=#00ff00>+72</color>\n\n72 <color=#00ff00>+72</color>\n\n144 <color=#00ff00>+72</color>\n\n180 <color=#00ff00>+72</color>\n\n108 <color=#00ff00>+72</color>\n\n252 <color=#00ff00>+72</color>\n\n144 <color=#00ff00>+72</color>\n\n72 <color=#00ff00>+72</color> | AI13: Increases troop defense。@Dwarf Infantry\n\nCrossbowman\n\nDwarf Bomber\n\nMagic Guard\n\nEagle Rider\n\nHeavy Knight\n\nCannon\n\nDragon Knight@144 <color=#00ff00>+72</color>\n\n72 <color=#00ff00>+72</color>\n\n144 <color=#00ff00>+72</color>\n\n180 <color=#00ff00>+72</color>\n\n108 <color=#00ff00>+72</color>\n\n252 <color=#00ff00>+72</color>\n\n144 <color=#00ff00>+72</color>\n\n72 <color=#00ff00>+72</color> | AJ13: 研究后增加士兵防御力。@矮人步兵\n\n弩手\n\n矮人直升机\n\n魔法守卫\n\n鹰骑士\n\n骑士\n\n炮车\n\n龙骑士@144 <color=#00ff00>+72</color>\n\n72 <color=#00ff00>+72</color>\n\n144 <color=#00ff00>+72</color>\n\n180 <color=#00ff00>+72</color>\n\n108 <color=#00ff00>+72</color>\n\n252 <color=#00ff00>+72</color>\n\n144 <color=#00ff00>+72</color>\n\n72 <color=#00ff00>+72</color>
A14: 10005003 | B14: 防御升级3 | D14: =LEFT(A14,6) -> 100050 | E14: =RIGHT(A14,1) -> 3 | F14: 3 | G14: 人族 | H14: 团队科技 | I14: 团队防御升级科技 | J14: 60000 | K14: 800 | N14: 3 | T14: 科技效果_提升单位攻防属性 | U14: 护甲值 | AD14: UITexture/Charactar/keji/hum_tech_defence3 | AE14: 高级防御 | AF14: 高级防御 | AG14: 高级防御 | AH14: 研究后增加士兵防御力。@矮人步兵\n\n弩手\n\n矮人直升机\n\n魔法守卫\n\n鹰骑士\n\n骑士\n\n炮车\n\n龙骑士@216 <color=#00ff00>+72</color>\n\n144 <color=#00ff00>+72</color>\n\n216 <color=#00ff00>+72</color>\n\n252 <color=#00ff00>+72</color>\n\n180 <color=#00ff00>+72</color>\n\n324 <color=#00ff00>+72</color>\n\n216 <color=#00ff00>+72</color>\n\n144 <color=#00ff00>+72</color> | AI14: Increases troop defense。@Dwarf Infantry\n\nCrossbowman\n\nDwarf Bomber\n\nMagic Guard\n\nEagle Rider\n\nHeavy Knight\n\nCannon\n\nDragon Knight@216 <color=#00ff00>+72</color>\n\n144 <color=#00ff00>+72</color>\n\n216 <color=#00ff00>+72</color>\n\n252 <color=#00ff00>+72</color>\n\n180 <color=#00ff00>+72</color>\n\n324 <color=#00ff00>+72</color>\n\n216 <color=#00ff00>+72</color>\n\n144 <color=#00ff00>+72</color> | AJ14: 研究后增加士兵防御力。@矮人步兵\n\n弩手\n\n矮人直升机\n\n魔法守卫\n\n鹰骑士\n\n骑士\n\n炮车\n\n龙骑士@216 <color=#00ff00>+72</color>\n\n144 <color=#00ff00>+72</color>\n\n216 <color=#00ff00>+72</color>\n\n252 <color=#00ff00>+72</color>\n\n180 <color=#00ff00>+72</color>\n\n324 <color=#00ff00>+72</color>\n\n216 <color=#00ff00>+72</color>\n\n144 <color=#00ff00>+72</color>
A15: 10006001 | B15: 初始步兵 | D15: =LEFT(A15,6) -> 100060 | E15: =RIGHT(A15,1) -> 1 | F15: 1 | G15: 人族 | H15: 单位科技 | J15: 0 | K15: 0 | N15: 1 | T15: 科技效果_孵化单位 | U15: 20000101 | V15: 1
A16: 10007001 | B16: 3v3人口升级1 | D16: =LEFT(A16,6) -> 100070 | E16: =RIGHT(A16,1) -> 1 | F16: 4 | G16: 人族 | H16: 团队科技 | I16: 团队人口升级科技 | J16: 20000 | K16: 250 | N16: 1 | T16: 科技效果_提升最大人口 | U16: 5 | AD16: UITexture/Charactar/keji/food_1 | AE16: 人口升级 | AF16: 人口升级 | AG16: 人口升级 | AH16: 研究后增加5人口。 | AI16: Increases Supply Cap by 5 | AJ16: 研究后增加5人口。
A17: 10007002 | B17: 3v3人口升级2 | D17: =LEFT(A17,6) -> 100070 | E17: =RIGHT(A17,1) -> 2 | F17: 4 | G17: 人族 | H17: 团队科技 | I17: 团队人口升级科技 | J17: 20000 | K17: 250 | N17: 1 | T17: 科技效果_提升最大人口 | U17: 5 | AD17: UITexture/Charactar/keji/food_1 | AE17: 人口升级 | AF17: 人口升级 | AG17: 人口升级 | AH17: 研究后增加5人口。 | AI17: Increases Supply Cap by 5 | AJ17: 研究后增加5人口。
A18: 10007003 | B18: 3v3人口升级3 | D18: =LEFT(A18,6) -> 100070 | E18: =RIGHT(A18,1) -> 3 | F18: 4 | G18: 人族 | H18: 团队科技 | I18: 团队人口升级科技 | J18: 20000 | K18: 250 | N18: 1 | T18: 科技效果_提升最大人口 | U18: 5 | AD18: UITexture/Charactar/keji/food_1 | AE18: 人口升级 | AF18: 人口升级 | AG18: 人口升级 | AH18: 研究后增加5人口。 | AI18: Increases Supply Cap by 5 | AJ18: 研究后增加5人口。
A19: 10007004 | B19: 3v3人口升级4 | D19: =LEFT(A19,6) -> 100070 | E19: =RIGHT(A19,1) -> 4 | F19: 4 | G19: 人族 | H19: 团队科技 | I19: 团队人口升级科技 | J19: 20000 | K19: 250 | N19: 1 | T19: 科技效果_提升最大人口 | U19: 5 | AD19: UITexture/Charactar/keji/food_1 | AE19: 人口升级 | AF19: 人口升级 | AG19: 人口升级 | AH19: 研究后增加5人口。 | AI19: Increases Supply Cap by 5 | AJ19: 研究后增加5人口。
A20: 10008001 | B20: 1v1升级一级基地 | D20: =LEFT(A20,6) -> 100080 | E20: =RIGHT(A20,1) -> 1 | F20: 1 | G20: 人族 | H20: 单位科技 | I20: 单位基地升级科技 | J20: 0 | K20: 0 | N20: 1 | T20: 科技效果_基地科技升级 | U20: 20000127 | Y20: 科技效果_提升最大人口 | Z20: 10 | AD20: UITexture/Charactar/renlei/hum_base01 | AE20: 一级城堡 | AF20: 一级城堡 | AG20: 一级城堡 | AH20: 可以升级至二级城堡，升级后可解锁中级兵种和中级科技，可提高基地和副基地、防御塔的战斗力，提升金矿防御力。保护基地不被摧毁对获得战争的胜利至关重要！ | AI20: Can be upgraded to level 2 castle, after upgrading intermediate Troops and Tech will be unlocked. It also increases combat effectiveness of base and secondary base. Protecting your base is vital to winning! | AJ20: 可以升级至二级城堡，升级后可解锁中级兵种和中级科技，可提高基地和副基地、防御塔的战斗力，提升金矿防御力。保护基地不被摧毁对获得战争的胜利至关重要！
A21: 10009001 | B21: 1v1升级二级基地 | D21: =LEFT(A21,6) -> 100090 | E21: =RIGHT(A21,1) -> 1 | F21: 1 | G21: 人族 | H21: 单位科技 | I21: 单位基地升级科技 | J21: 75000 | K21: 1000 | N21: 1 | T21: 科技效果_基地科技升级 | U21: 20000128 | AD21: UITexture/Charactar/renlei/hum_base02 | AE21: 二级城堡 | AF21: 二级城堡 | AG21: 二级城堡 | AH21: 可以升级至三级城堡，升级后可解锁高级兵种和高级科技，可提高基地和副基地、防御塔的战斗力，提升金矿防御力。保护基地不被摧毁对获得战争的胜利至关重要！ | AI21: Can be upgraded to level 3 castle. After upgrading, advanced Troops and Tech will be unlocked. It also increases combat effectiveness of base and secondary base. Protecting your base is vital to winning! | AJ21: 可以升级至三级城堡，升级后可解锁高级兵种和高级科技，可提高基地和副基地、防御塔的战斗力，提升金矿防御力。保护基地不被摧毁对获得战争的胜利至关重要！
A22: 10010001 | B22: 1v1升级三级基地 | D22: =LEFT(A22,6) -> 100100 | E22: =RIGHT(A22,1) -> 1 | F22: 1 | G22: 人族 | H22: 单位科技 | I22: 单位基地升级科技 | J22: 90000 | K22: 1000 | N22: 2 | T22: 科技效果_基地科技升级 | U22: 20000129 | AD22: UITexture/Charactar/renlei/hum_base03 | AE22: 三级城堡 | AF22: 三级城堡 | AG22: 三级城堡 | AH22: 可训练高级兵种和研究高级科技，可提高基地和副基地、防御塔的战斗力，提升金矿防御力。保护基地不被摧毁对获得战争的胜利至关重要！ | AI22: Can train high level Troops and research high level Tech. It also increases combat effectiveness of base and secondary base. Protecting your base is vital to winning! | AJ22: 可训练高级兵种和研究高级科技，可提高基地和副基地、防御塔的战斗力，提升金矿防御力。保护基地不被摧毁对获得战争的胜利至关重要！
A23: 10011001 | B23: army01建造 | C23: 科技树类型1 | D23: =LEFT(A23,6) -> 100110 | E23: =RIGHT(A23,1) -> 1 | F23: 1 | G23: 人族 | H23: 单位科技 | I23: 单位训练科技 | J23: 16000 | K23: 180 | L23: =0.6*K23 -> 108 | M23: 0 | N23: 1 | Q23: 10000
A24: 10011101 | B24: army01技能Q | C24: 科技树类型1 | D24: =LEFT(A24,6) -> 100111 | E24: =RIGHT(A24,1) -> 1 | F24: 1 | G24: 人族 | H24: 单位科技 | J24: 0 | K24: 0 | N24: 1 | T24: 科技效果_解锁单位技能 | U24: 20000101 | V24: 技能栏Q
A25: 10012001 | B25: army02建造 | C25: 科技树类型1 | D25: =LEFT(A25,6) -> 100120 | E25: =RIGHT(A25,1) -> 1 | F25: 1 | G25: 人族 | H25: 单位科技 | I25: 单位训练科技 | J25: 22000 | K25: 250 | L25: =0.6*K25 -> 150 | M25: 0 | N25: 1 | Q25: 10000
A26: 10012101 | B26: army02技能Q | C26: 科技树类型1 | D26: =LEFT(A26,6) -> 100121 | E26: =RIGHT(A26,1) -> 1 | F26: 1 | G26: 人族 | H26: 单位科技 | J26: 0 | K26: 0 | N26: 2 | T26: 科技效果_解锁单位技能 | U26: 20000102 | V26: 技能栏Q
A27: 10013001 | B27: army03建造 | C27: 科技树类型1 | D27: =LEFT(A27,6) -> 100130 | E27: =RIGHT(A27,1) -> 1 | F27: 1 | G27: 人族 | H27: 单位科技 | I27: 单位训练科技 | J27: 20000 | K27: 240 | L27: =0.6*K27 -> 144 | M27: 340 | N27: 2 | Q27: 10000
A28: 10013101 | B28: army03技能Q | C28: 科技树类型1 | D28: =LEFT(A28,6) -> 100131 | E28: =RIGHT(A28,1) -> 1 | F28: 1 | G28: 人族 | H28: 单位科技 | J28: 0 | K28: 0 | N28: 2 | T28: 科技效果_解锁单位技能 | U28: 20000103 | V28: 技能栏Q
A29: 10013201 | B29: army03技能W | C29: 科技树类型1 | D29: =LEFT(A29,6) -> 100132 | E29: =RIGHT(A29,1) -> 1 | F29: 1 | G29: 人族 | H29: 单位科技 | J29: 0 | K29: 0 | N29: 3 | T29: 科技效果_解锁单位技能 | U29: 20000103 | V29: 技能栏W
A30: 10014001 | B30: army04建造 | C30: 科技树类型1 | D30: =LEFT(A30,6) -> 100140 | E30: =RIGHT(A30,1) -> 1 | F30: 1 | G30: 人族 | H30: 单位科技 | I30: 单位训练科技 | J30: 17000 | K30: 210 | L30: =0.6*K30 -> 126 | M30: 340 | N30: 2 | Q30: 10000
A31: 10014101 | B31: army04技能Q | C31: 科技树类型1 | D31: =LEFT(A31,6) -> 100141 | E31: =RIGHT(A31,1) -> 1 | F31: 1 | G31: 人族 | H31: 单位科技 | J31: 0 | K31: 0 | N31: 2 | T31: 科技效果_解锁单位技能 | U31: 20000104 | V31: 技能栏Q
A32: 10014201 | B32: army04技能W | C32: 科技树类型1 | D32: =LEFT(A32,6) -> 100142 | E32: =RIGHT(A32,1) -> 1 | F32: 1 | G32: 人族 | H32: 单位科技 | J32: 0 | K32: 0 | N32: 2 | T32: 科技效果_解锁单位技能 | U32: 20000104 | V32: 技能栏W
A33: 10014301 | B33: army04技能E | C33: 科技树类型1 | D33: =LEFT(A33,6) -> 100143 | E33: =RIGHT(A33,1) -> 1 | F33: 1 | G33: 人族 | H33: 单位科技 | J33: 0 | K33: 0 | N33: 3 | T33: 科技效果_解锁单位技能 | U33: 20000104 | V33: 技能栏E
A34: 10015001 | B34: army05建造 | C34: 科技树类型2 | D34: =LEFT(A34,6) -> 100150 | E34: =RIGHT(A34,1) -> 1 | F34: 1 | G34: 人族 | H34: 单位科技 | I34: 单位训练科技 | J34: 18000 | K34: 200 | L34: =0.6*K34 -> 120 | M34: 340 | N34: 2 | Q34: 10000
A35: 10015101 | B35: army05技能Q | C35: 科技树类型2 | D35: =LEFT(A35,6) -> 100151 | E35: =RIGHT(A35,1) -> 1 | F35: 1 | G35: 人族 | H35: 单位科技 | J35: 0 | K35: 0 | N35: 2 | T35: 科技效果_解锁单位技能 | U35: 20000105 | V35: 技能栏Q
A36: 10016001 | B36: army06建造 | C36: 科技树类型3 | D36: =LEFT(A36,6) -> 100160 | E36: =RIGHT(A36,1) -> 1 | F36: 1 | G36: 人族 | H36: 单位科技 | I36: 单位训练科技 | J36: 22000 | K36: 260 | L36: =0.6*K36 -> 156 | M36: 440 | N36: 2 | Q36: 10000
A37: 10016101 | B37: army06技能Q | C37: 科技树类型3 | D37: =LEFT(A37,6) -> 100161 | E37: =RIGHT(A37,1) -> 1 | F37: 1 | G37: 人族 | H37: 单位科技 | J37: 0 | K37: 0 | N37: 2 | T37: 科技效果_解锁单位技能 | U37: 20000106 | V37: 技能栏Q
A38: 10016201 | B38: army06技能W | C38: 科技树类型3 | D38: =LEFT(A38,6) -> 100162 | E38: =RIGHT(A38,1) -> 1 | F38: 1 | G38: 人族 | H38: 单位科技 | J38: 0 | K38: 0 | N38: 2 | T38: 科技效果_解锁单位技能 | U38: 20000106 | V38: 技能栏W
A39: 10016301 | B39: army06技能E | C39: 科技树类型3 | D39: =LEFT(A39,6) -> 100163 | E39: =RIGHT(A39,1) -> 1 | F39: 1 | G39: 人族 | H39: 单位科技 | J39: 0 | K39: 0 | N39: 2 | T39: 科技效果_解锁单位技能 | U39: 20000106 | V39: 技能栏E
A40: 10017001 | B40: army07建造 | C40: 科技树类型4 | D40: =LEFT(A40,6) -> 100170 | E40: =RIGHT(A40,1) -> 1 | F40: 1 | G40: 人族 | H40: 单位科技 | I40: 单位训练科技 | J40: 22000 | K40: 240 | L40: =0.6*K40 -> 144 | M40: 470 | N40: 2 | Q40: 10000
...

Sheet 基地升级科技效果
A1: 主基地ID | B1: 主基地科技图标 | C1: 备注 | D1: 基地等级类型 | E1: 副基地ID | F1: 科技入口ID | G1: 科技研究完成1ID | H1: 科技研究完成1科技树类型 | I1: 科技研究完成2ID | J1: 科技研究完成2科技树类型 | K1: 科技研究完成3ID | L1: 科技研究完成3科技树类型 | M1: 科技研究完成4ID | N1: 科技研究完成4科技树类型 | O1: 科技研究完成5ID | P1: 科技研究完成5科技树类型 | Q1: 科技研究完成6ID | R1: 科技研究完成6科技树类型 | S1: 科技研究完成7ID | T1: 科技研究完成7科技树类型 | U1: 科技研究完成8ID | V1: 科技研究完成8科技树类型 | W1: 科技研究完成9ID | X1: 科技研究完成9科技树类型 | Y1: 科技研究完成10ID | Z1: 科技研究完成10科技树类型 | AA1: 科技研究完成11ID | AB1: 科技研究完成11科技树类型 | AC1: 科技研究完成12ID | AD1: 科技研究完成12科技树类型 | AE1: 科技研究完成13ID | AF1: 科技研究完成13科技树类型 | AG1: 科技研究完成14ID | AH1: 科技研究完成14科技树类型 | AI1: 科技研究完成15ID | AJ1: 科技研究完成15科技树类型 | AK1: 科技研究完成16ID | AL1: 科技研究完成16科技树类型 | AM1: 科技研究完成17ID | AN1: 科技研究完成17科技树类型 | AO1: 科技研究完成18ID | AP1: 科技研究完成18科技树类型 | AQ1: 科技研究完成19ID | AR1: 科技研究完成19科技树类型 | AS1: 科技研究完成20ID | AT1: 科技研究完成20科技树类型 | AU1: 科技解锁1ID | AV1: 科技解锁1科技树类型 | AW1: 科技解锁2ID | AX1: 科技解锁2科技树类型 | AY1: 科技解锁3ID | AZ1: 科技解锁3科技树类型 | BA1: 科技解锁4ID | BB1: 科技解锁4科技树类型 | BC1: 科技解锁5ID | BD1: 科技解锁5科技树类型 | BE1: 科技解锁6ID | BF1: 科技解锁6科技树类型 | BG1: 科技解锁7ID | BH1: 科技解锁7科技树类型 | BI1: 科技解锁8ID | BJ1: 科技解锁8科技树类型
A2: 20000117 | B2: UITexture/Charactar/renlei/hum_base01 | C2: 3v3 | D2: 一本科技基地 | E2: 20000112 | F2: 10000001 | G2: 10011001 | H2: =VLOOKUP($G2,科技表!$1:$1048576,3,0) -> 科技树类型1 | I2: 10011101 | J2: =VLOOKUP($I2,科技表!$1:$1048576,3,0) -> 科技树类型1 | K2: 10012001 | L2: =VLOOKUP($K2,科技表!$1:$1048576,3,0) -> 科技树类型1 | M2: 10006001 | O2: 10022001 | Q2: 10021001 | AU2: 10001001 | AW2: 10007001 | AY2: 10004001 | BA2: 10005001
A3: 20000118 | B3: UITexture/Charactar/renlei/hum_base02 | C3: 3v3 | D3: 二本科技基地 | E3: 20000113 | G3: 10012101 | H3: =VLOOKUP($G3,科技表!$1:$1048576,3,0) -> 科技树类型1 | I3: 10013001 | J3: =VLOOKUP($I3,科技表!$1:$1048576,3,0) -> 科技树类型1 | K3: 10013101 | L3: =VLOOKUP($K3,科技表!$1:$1048576,3,0) -> 科技树类型1 | M3: 10014001 | N3: =VLOOKUP($M3,科技表!$1:$1048576,3,0) -> 科技树类型1 | O3: 10014101 | P3: =VLOOKUP($O3,科技表!$1:$1048576,3,0) -> 科技树类型1 | Q3: 10014201 | R3: =VLOOKUP($Q3,科技表!$1:$1048576,3,0) -> 科技树类型1 | S3: 10015001 | T3: =VLOOKUP($S3,科技表!$1:$1048576,3,0) -> 科技树类型2 | U3: 10015101 | V3: =VLOOKUP($U3,科技表!$1:$1048576,3,0) -> 科技树类型2 | W3: 10016001 | X3: =VLOOKUP($W3,科技表!$1:$1048576,3,0) -> 科技树类型3 | Y3: 10016101 | Z3: =VLOOKUP($Y3,科技表!$1:$1048576,3,0) -> 科技树类型3 | AA3: 10016201 | AB3: =VLOOKUP($AA3,科技表!$1:$1048576,3,0) -> 科技树类型3 | AC3: 10016301 | AD3: =VLOOKUP($AC3,科技表!$1:$1048576,3,0) -> 科技树类型3 | AE3: 10017001 | AF3: =VLOOKUP($AE3,科技表!$1:$1048576,3,0) -> 科技树类型4 | AG3: 10017101 | AH3: =VLOOKUP($AG3,科技表!$1:$1048576,3,0) -> 科技树类型4 | AI3: 10021101 | AK3: 10022101 | AU3: 10002001
A4: 20000119 | B4: UITexture/Charactar/renlei/hum_base03 | C4: 3v3 | D4: 三本科技基地 | E4: 20000114 | G4: 10013201 | H4: =VLOOKUP($G4,科技表!$1:$1048576,3,0) -> 科技树类型1 | I4: 10014301 | J4: =VLOOKUP($I4,科技表!$1:$1048576,3,0) -> 科技树类型1 | K4: 10018001 | L4: =VLOOKUP($K4,科技表!$1:$1048576,3,0) -> 科技树类型2 | M4: 10018101 | N4: =VLOOKUP($M4,科技表!$1:$1048576,3,0) -> 科技树类型2 | O4: 10019001 | P4: =VLOOKUP($O4,科技表!$1:$1048576,3,0) -> 科技树类型3 | Q4: 10019101 | R4: =VLOOKUP($Q4,科技表!$1:$1048576,3,0) -> 科技树类型3 | S4: 10020001 | T4: =VLOOKUP($S4,科技表!$1:$1048576,3,0) -> 科技树类型4 | U4: 10020101 | V4: =VLOOKUP($U4,科技表!$1:$1048576,3,0) -> 科技树类型4 | W4: 10021201 | Y4: 10022201
A5: 20000217 | B5: UITexture/Charactar/shouzu/orc_base01 | C5: 3v3 | D5: 一本科技基地 | E5: 20000212 | F5: 11000001 | G5: 11011001 | H5: =VLOOKUP($G5,科技表!$1:$1048576,3,0) -> 科技树类型1 | I5: 11012001 | J5: =VLOOKUP($I5,科技表!$1:$1048576,3,0) -> 科技树类型1 | K5: 11006001 | M5: 11022001 | O5: 11021001 | AU5: 11001001 | AW5: 11007001 | AY5: 11004001 | BA5: 11005001
A6: 20000218 | B6: UITexture/Charactar/shouzu/orc_base02 | C6: 3v3 | D6: 二本科技基地 | E6: 20000213 | G6: 11011101 | H6: =VLOOKUP($G6,科技表!$1:$1048576,3,0) -> 科技树类型1 | I6: 11012101 | J6: =VLOOKUP($I6,科技表!$1:$1048576,3,0) -> 科技树类型1 | K6: 11013001 | L6: =VLOOKUP($K6,科技表!$1:$1048576,3,0) -> 科技树类型1 | M6: 11013101 | N6: =VLOOKUP($M6,科技表!$1:$1048576,3,0) -> 科技树类型1 | O6: 11014001 | P6: =VLOOKUP($O6,科技表!$1:$1048576,3,0) -> 科技树类型1 | Q6: 11014101 | R6: =VLOOKUP($Q6,科技表!$1:$1048576,3,0) -> 科技树类型1 | S6: 11015001 | T6: =VLOOKUP($S6,科技表!$1:$1048576,3,0) -> 科技树类型2 | U6: 11015101 | V6: =VLOOKUP($U6,科技表!$1:$1048576,3,0) -> 科技树类型2 | W6: 11015201 | X6: =VLOOKUP($W6,科技表!$1:$1048576,3,0) -> 科技树类型2 | Y6: 11016001 | Z6: =VLOOKUP($Y6,科技表!$1:$1048576,3,0) -> 科技树类型3 | AA6: 11016101 | AB6: =VLOOKUP($AA6,科技表!$1:$1048576,3,0) -> 科技树类型3 | AC6: 11016201 | AD6: =VLOOKUP($AA6,科技表!$1:$1048576,3,0) -> 科技树类型3 | AE6: 11017001 | AF6: =VLOOKUP($AE6,科技表!$1:$1048576,3,0) -> 科技树类型4 | AG6: 11017101 | AH6: =VLOOKUP($AG6,科技表!$1:$1048576,3,0) -> 科技树类型4 | AI6: 11018001 | AJ6: =VLOOKUP($AI6,科技表!$1:$1048576,3,0) -> 科技树类型4 | AK6: 11018101 | AL6: =VLOOKUP($AK6,科技表!$1:$1048576,3,0) -> 科技树类型4 | AM6: 11021101 | AO6: 11022101 | AQ6: 11013301 | AR6: =VLOOKUP($AQ6,科技表!$1:$1048576,3,0) -> 科技树类型1 | AU6: 11002001
A7: 20000219 | B7: UITexture/Charactar/shouzu/orc_base03 | C7: 3v3 | D7: 三本科技基地 | E7: 20000214 | G7: 11013201 | H7: =VLOOKUP($G7,科技表!$1:$1048576,3,0) -> 科技树类型1 | I7: 11014201 | J7: =VLOOKUP($I7,科技表!$1:$1048576,3,0) -> 科技树类型1 | K7: 11015301 | L7: =VLOOKUP($K7,科技表!$1:$1048576,3,0) -> 科技树类型2 | M7: 11019001 | N7: =VLOOKUP($M7,科技表!$1:$1048576,3,0) -> 科技树类型3 | O7: 11019101 | P7: =VLOOKUP($O7,科技表!$1:$1048576,3,0) -> 科技树类型3 | Q7: 11020001 | R7: =VLOOKUP($Q7,科技表!$1:$1048576,3,0) -> 科技树类型2 | S7: 11020101 | T7: =VLOOKUP($S7,科技表!$1:$1048576,3,0) -> 科技树类型2 | U7: 11021201 | W7: 11022201
A8: 20000316 | B8: UITexture/Charactar/wangling/gho_base01 | C8: 3v3 | D8: 一本科技基地 | E8: 20000312 | F8: 12000001 | G8: 12011001 | H8: =VLOOKUP($G8,科技表!$1:$1048576,3,0) -> 科技树类型1 | I8: 12011101 | J8: =VLOOKUP($I8,科技表!$1:$1048576,3,0) -> 科技树类型1 | K8: 12012001 | L8: =VLOOKUP($K8,科技表!$1:$1048576,3,0) -> 科技树类型1 | M8: 12006001 | O8: 12022001 | Q8: 12021001 | AU8: 12001001 | AW8: 12007001 | AY8: 12004001 | BA8: 12005001
A9: 20000317 | B9: UITexture/Charactar/wangling/gho_base02 | C9: 3v3 | D9: 二本科技基地 | E9: 20000313 | G9: 12011201 | H9: =VLOOKUP($G9,科技表!$1:$1048576,3,0) -> 科技树类型1 | I9: 12012101 | J9: =VLOOKUP($I9,科技表!$1:$1048576,3,0) -> 科技树类型1 | K9: 12013001 | L9: =VLOOKUP($K9,科技表!$1:$1048576,3,0) -> 科技树类型1 | M9: 12013101 | N9: =VLOOKUP($M9,科技表!$1:$1048576,3,0) -> 科技树类型1 | O9: 12014001 | P9: =VLOOKUP($O9,科技表!$1:$1048576,3,0) -> 科技树类型1 | Q9: 12014101 | R9: =VLOOKUP($Q9,科技表!$1:$1048576,3,0) -> 科技树类型1 | S9: 12015001 | T9: =VLOOKUP($S9,科技表!$1:$1048576,3,0) -> 科技树类型3 | U9: 12015101 | V9: =VLOOKUP($U9,科技表!$1:$1048576,3,0) -> 科技树类型3 | W9: 12015201 | X9: =VLOOKUP($W9,科技表!$1:$1048576,3,0) -> 科技树类型3 | Y9: 12016001 | Z9: =VLOOKUP($Y9,科技表!$1:$1048576,3,0) -> 科技树类型4 | AA9: 12016101 | AB9: =VLOOKUP($AA9,科技表!$1:$1048576,3,0) -> 科技树类型4 | AC9: 12017001 | AD9: =VLOOKUP($AC9,科技表!$1:$1048576,3,0) -> 科技树类型2 | AE9: 12017101 | AF9: =VLOOKUP($AE9,科技表!$1:$1048576,3,0) -> 科技树类型2 | AG9: 12021101 | AI9: 12022101 | AU9: 12002001
A10: 20000318 | B10: UITexture/Charactar/wangling/gho_base03 | C10: 3v3 | D10: 三本科技基地 | E10: 20000314 | G10: 12013201 | H10: =VLOOKUP($G10,科技表!$1:$1048576,3,0) -> 科技树类型1 | I10: 12014201 | J10: =VLOOKUP($I10,科技表!$1:$1048576,3,0) -> 科技树类型1 | K10: 12018001 | L10: =VLOOKUP($K10,科技表!$1:$1048576,3,0) -> 科技树类型2 | M10: 12018101 | N10: =VLOOKUP($M10,科技表!$1:$1048576,3,0) -> 科技树类型2 | O10: 12019001 | P10: =VLOOKUP($O10,科技表!$1:$1048576,3,0) -> 科技树类型4 | Q10: 12019101 | R10: =VLOOKUP($Q10,科技表!$1:$1048576,3,0) -> 科技树类型4 | S10: 12020001 | T10: =VLOOKUP($S10,科技表!$1:$1048576,3,0) -> 科技树类型3 | U10: 12020101 | V10: =VLOOKUP($U10,科技表!$1:$1048576,3,0) -> 科技树类型3 | W10: 12020201 | X10: =VLOOKUP($W10,科技表!$1:$1048576,3,0) -> 科技树类型3 | Y10: 12020301 | Z10: =VLOOKUP($Y10,科技表!$1:$1048576,3,0) -> 科技树类型3 | AA10: 12021201 | AC10: 12017201 | AD10: =VLOOKUP($AC10,科技表!$1:$1048576,3,0) -> 科技树类型2 | AE10: 12023101 | AG10: 12024101 | AI10: 12015011 | AJ10: =VLOOKUP($AI10,科技表!$1:$1048576,3,0) -> 科技树类型3 | AK10: 12022201
A11: 20000417 | B11: UITexture/Charactar/jingling/elf_base01 | C11: 3v3 | D11: 一本科技基地 | E11: 20000412 | F11: 13000001 | G11: 13011001 | H11: =VLOOKUP($G11,科技表!$1:$1048576,3,0) -> 科技树类型1 | I11: 13011101 | J11: =VLOOKUP($I11,科技表!$1:$1048576,3,0) -> 科技树类型1 | K11: 13011201 | L11: =VLOOKUP($K11,科技表!$1:$1048576,3,0) -> 科技树类型1 | M11: 13012001 | N11: =VLOOKUP($M11,科技表!$1:$1048576,3,0) -> 科技树类型1 | O11: 13006001 | Q11: 13022001 | S11: 13021001 | U11: 13023001 | AU11: 13001001 | AW11: 13007001 | AY11: 13004001 | BA11: 13005001
A12: 20000418 | B12: UITexture/Charactar/jingling/elf_base02 | C12: 3v3 | D12: 二本科技基地 | E12: 20000413 | G12: 13012101 | H12: =VLOOKUP($G12,科技表!$1:$1048576,3,0) -> 科技树类型1 | I12: 13013001 | J12: =VLOOKUP($I12,科技表!$1:$1048576,3,0) -> 科技树类型1 | K12: 13013101 | L12: =VLOOKUP($K12,科技表!$1:$1048576,3,0) -> 科技树类型1 | M12: 13014001 | N12: =VLOOKUP($M12,科技表!$1:$1048576,3,0) -> 科技树类型3 | O12: 13014101 | P12: =VLOOKUP($O12,科技表!$1:$1048576,3,0) -> 科技树类型3 | Q12: 13014201 | R12: =VLOOKUP($Q12,科技表!$1:$1048576,3,0) -> 科技树类型3 | S12: 13015001 | T12: =VLOOKUP($S12,科技表!$1:$1048576,3,0) -> 科技树类型3 | U12: 13015101 | V12: =VLOOKUP($U12,科技表!$1:$1048576,3,0) -> 科技树类型3 | W12: 13015201 | X12: =VLOOKUP($W12,科技表!$1:$1048576,3,0) -> 科技树类型3 | Y12: 13016001 | Z12: =VLOOKUP($Y12,科技表!$1:$1048576,3,0) -> 科技树类型4 | AA12: 13016101 | AB12: =VLOOKUP($AA12,科技表!$1:$1048576,3,0) -> 科技树类型4 | AC12: 13017001 | AD12: =VLOOKUP($AC12,科技表!$1:$1048576,3,0) -> 科技树类型1 | AE12: 13017101 | AF12: =VLOOKUP($AE12,科技表!$1:$1048576,3,0) -> 科技树类型1 | AG12: 13017201 | AH12: =VLOOKUP($AG12,科技表!$1:$1048576,3,0) -> 科技树类型1 | AI12: 13017301 | AJ12: =VLOOKUP($AI12,科技表!$1:$1048576,3,0) -> 科技树类型1 | AK12: 13018001 | AL12: =VLOOKUP($AK12,科技表!$1:$1048576,3,0) -> 科技树类型2 | AM12: 13018101 | AN12: =VLOOKUP($AM12,科技表!$1:$1048576,3,0) -> 科技树类型2 | AO12: 13021101 | AQ12: 13022101 | AU12: 13002001
A13: 20000419 | B13: UITexture/Charactar/jingling/elf_base03 | C13: 3v3 | D13: 三本科技基地 | E13: 20000414 | G13: 13013201 | H13: =VLOOKUP($G13,科技表!$1:$1048576,3,0) -> 科技树类型1 | I13: 13015301 | J13: =VLOOKUP($I13,科技表!$1:$1048576,3,0) -> 科技树类型3 | K13: 13019001 | L13: =VLOOKUP($K13,科技表!$1:$1048576,3,0) -> 科技树类型2 | M13: 13019101 | N13: =VLOOKUP($M13,科技表!$1:$1048576,3,0) -> 科技树类型2 | O13: 13019201 | P13: =VLOOKUP($O13,科技表!$1:$1048576,3,0) -> 科技树类型2 | Q13: 13020001 | R13: =VLOOKUP($Q13,科技表!$1:$1048576,3,0) -> 科技树类型4 | S13: 13020101 | T13: =VLOOKUP($S13,科技表!$1:$1048576,3,0) -> 科技树类型4 | U13: 13021201 | W13: 13022201
A14: 20000127 | B14: UITexture/Charactar/renlei/hum_base01 | C14: 1v1 | D14: 一本科技基地 | E14: 20000124 | F14: 10008001 | G14: 10011001 | H14: =VLOOKUP($G14,科技表!$1:$1048576,3,0) -> 科技树类型1 | I14: 10011101 | J14: =VLOOKUP($I14,科技表!$1:$1048576,3,0) -> 科技树类型1 | K14: 10012001 | L14: =VLOOKUP($K14,科技表!$1:$1048576,3,0) -> 科技树类型1 | M14: 10006001 | O14: 10022001 | Q14: 10021001 | AU14: 10009001 | AW14: 10003001 | AY14: 10004001 | BA14: 10005001
A15: 20000128 | B15: UITexture/Charactar/renlei/hum_base02 | C15: 1v1 | D15: 二本科技基地 | E15: 20000125 | G15: 10012101 | H15: =VLOOKUP($G15,科技表!$1:$1048576,3,0) -> 科技树类型1 | I15: 10013001 | J15: =VLOOKUP($I15,科技表!$1:$1048576,3,0) -> 科技树类型1 | K15: 10013101 | L15: =VLOOKUP($K15,科技表!$1:$1048576,3,0) -> 科技树类型1 | M15: 10014001 | N15: =VLOOKUP($M15,科技表!$1:$1048576,3,0) -> 科技树类型1 | O15: 10014101 | P15: =VLOOKUP($O15,科技表!$1:$1048576,3,0) -> 科技树类型1 | Q15: 10014201 | R15: =VLOOKUP($Q15,科技表!$1:$1048576,3,0) -> 科技树类型1 | S15: 10015001 | T15: =VLOOKUP($S15,科技表!$1:$1048576,3,0) -> 科技树类型2 | U15: 10015101 | V15: =VLOOKUP($U15,科技表!$1:$1048576,3,0) -> 科技树类型2 | W15: 10016001 | X15: =VLOOKUP($W15,科技表!$1:$1048576,3,0) -> 科技树类型3 | Y15: 10016101 | Z15: =VLOOKUP($Y15,科技表!$1:$1048576,3,0) -> 科技树类型3 | AA15: 10016201 | AB15: =VLOOKUP($AA15,科技表!$1:$1048576,3,0) -> 科技树类型3 | AC15: 10016301 | AD15: =VLOOKUP($AC15,科技表!$1:$1048576,3,0) -> 科技树类型3 | AE15: 10017001 | AF15: =VLOOKUP($AE15,科技表!$1:$1048576,3,0) -> 科技树类型4 | AG15: 10017101 | AH15: =VLOOKUP($AG15,科技表!$1:$1048576,3,0) -> 科技树类型4 | AI15: 10021101 | AK15: 10022101 | AU15: 10010001
A16: 20000129 | B16: UITexture/Charactar/renlei/hum_base03 | C16: 1v1 | D16: 三本科技基地 | E16: 20000126 | G16: 10013201 | H16: =VLOOKUP($G16,科技表!$1:$1048576,3,0) -> 科技树类型1 | I16: 10014301 | J16: =VLOOKUP($I16,科技表!$1:$1048576,3,0) -> 科技树类型1 | K16: 10018001 | L16: =VLOOKUP($K16,科技表!$1:$1048576,3,0) -> 科技树类型2 | M16: 10018101 | N16: =VLOOKUP($M16,科技表!$1:$1048576,3,0) -> 科技树类型2 | O16: 10019001 | P16: =VLOOKUP($O16,科技表!$1:$1048576,3,0) -> 科技树类型3 | Q16: 10019101 | R16: =VLOOKUP($Q16,科技表!$1:$1048576,3,0) -> 科技树类型3 | S16: 10020001 | T16: =VLOOKUP($S16,科技表!$1:$1048576,3,0) -> 科技树类型4 | U16: 10020101 | V16: =VLOOKUP($U16,科技表!$1:$1048576,3,0) -> 科技树类型4 | W16: 10021201 | Y16: 10022201
A17: 20000228 | B17: UITexture/Charactar/shouzu/orc_base01 | C17: 1v1 | D17: 一本科技基地 | E17: 20000225 | F17: 11008001 | G17: 11011001 | H17: =VLOOKUP($G17,科技表!$1:$1048576,3,0) -> 科技树类型1 | I17: 11012001 | J17: =VLOOKUP($I17,科技表!$1:$1048576,3,0) -> 科技树类型1 | K17: 11006001 | M17: 11022001 | O17: 11021001 | AU17: 11009001 | AW17: 11003001 | AY17: 11004001 | BA17: 11005001
A18: 20000229 | B18: UITexture/Charactar/shouzu/orc_base02 | C18: 1v1 | D18: 二本科技基地 | E18: 20000226 | G18: 11011101 | H18: =VLOOKUP($G18,科技表!$1:$1048576,3,0) -> 科技树类型1 | I18: 11012101 | J18: =VLOOKUP($I18,科技表!$1:$1048576,3,0) -> 科技树类型1 | K18: 11013001 | L18: =VLOOKUP($K18,科技表!$1:$1048576,3,0) -> 科技树类型1 | M18: 11013101 | N18: =VLOOKUP($M18,科技表!$1:$1048576,3,0) -> 科技树类型1 | O18: 11014001 | P18: =VLOOKUP($O18,科技表!$1:$1048576,3,0) -> 科技树类型1 | Q18: 11014101 | R18: =VLOOKUP($Q18,科技表!$1:$1048576,3,0) -> 科技树类型1 | S18: 11015001 | T18: =VLOOKUP($S18,科技表!$1:$1048576,3,0) -> 科技树类型2 | U18: 11015101 | V18: =VLOOKUP($U18,科技表!$1:$1048576,3,0) -> 科技树类型2 | W18: 11015201 | X18: =VLOOKUP($W18,科技表!$1:$1048576,3,0) -> 科技树类型2 | Y18: 11016001 | Z18: =VLOOKUP($Y18,科技表!$1:$1048576,3,0) -> 科技树类型3 | AA18: 11016101 | AB18: =VLOOKUP($AA18,科技表!$1:$1048576,3,0) -> 科技树类型3 | AC18: 11016201 | AD18: =VLOOKUP($AA18,科技表!$1:$1048576,3,0) -> 科技树类型3 | AE18: 11017001 | AF18: =VLOOKUP($AE18,科技表!$1:$1048576,3,0) -> 科技树类型4 | AG18: 11017101 | AH18: =VLOOKUP($AG18,科技表!$1:$1048576,3,0) -> 科技树类型4 | AI18: 11018001 | AJ18: =VLOOKUP($AI18,科技表!$1:$1048576,3,0) -> 科技树类型4 | AK18: 11018101 | AL18: =VLOOKUP($AK18,科技表!$1:$1048576,3,0) -> 科技树类型4 | AM18: 11021101 | AO18: 11022101 | AQ18: 11013301 | AR18: =VLOOKUP($AQ18,科技表!$1:$1048576,3,0) -> 科技树类型1 | AU18: 11010001
A19: 20000230 | B19: UITexture/Charactar/shouzu/orc_base03 | C19: 1v1 | D19: 三本科技基地 | E19: 20000227 | G19: 11013201 | H19: =VLOOKUP($G19,科技表!$1:$1048576,3,0) -> 科技树类型1 | I19: 11014201 | J19: =VLOOKUP($I19,科技表!$1:$1048576,3,0) -> 科技树类型1 | K19: 11015301 | L19: =VLOOKUP($K19,科技表!$1:$1048576,3,0) -> 科技树类型2 | M19: 11019001 | N19: =VLOOKUP($M19,科技表!$1:$1048576,3,0) -> 科技树类型3 | O19: 11019101 | P19: =VLOOKUP($O19,科技表!$1:$1048576,3,0) -> 科技树类型3 | Q19: 11020001 | R19: =VLOOKUP($Q19,科技表!$1:$1048576,3,0) -> 科技树类型2 | S19: 11020101 | T19: =VLOOKUP($S19,科技表!$1:$1048576,3,0) -> 科技树类型2 | U19: 11021201 | W19: 11022201
A20: 20000323 | B20: UITexture/Charactar/wangling/gho_base01 | C20: 1v1 | D20: 一本科技基地 | E20: 20000320 | F20: 12008001 | G20: 12011001 | H20: =VLOOKUP($G20,科技表!$1:$1048576,3,0) -> 科技树类型1 | I20: 12011101 | J20: =VLOOKUP($I20,科技表!$1:$1048576,3,0) -> 科技树类型1 | K20: 12012001 | L20: =VLOOKUP($K20,科技表!$1:$1048576,3,0) -> 科技树类型1 | M20: 12006001 | O20: 12022001 | Q20: 12021001 | AU20: 12009001 | AW20: 12003001 | AY20: 12004001 | BA20: 12005001
A21: 20000324 | B21: UITexture/Charactar/wangling/gho_base02 | C21: 1v1 | D21: 二本科技基地 | E21: 20000321 | G21: 12011201 | H21: =VLOOKUP($G21,科技表!$1:$1048576,3,0) -> 科技树类型1 | I21: 12012101 | J21: =VLOOKUP($I21,科技表!$1:$1048576,3,0) -> 科技树类型1 | K21: 12013001 | L21: =VLOOKUP($K21,科技表!$1:$1048576,3,0) -> 科技树类型1 | M21: 12013101 | N21: =VLOOKUP($M21,科技表!$1:$1048576,3,0) -> 科技树类型1 | O21: 12014001 | P21: =VLOOKUP($O21,科技表!$1:$1048576,3,0) -> 科技树类型1 | Q21: 12014101 | R21: =VLOOKUP($Q21,科技表!$1:$1048576,3,0) -> 科技树类型1 | S21: 12015001 | T21: =VLOOKUP($S21,科技表!$1:$1048576,3,0) -> 科技树类型3 | U21: 12015101 | V21: =VLOOKUP($U21,科技表!$1:$1048576,3,0) -> 科技树类型3 | W21: 12015201 | X21: =VLOOKUP($W21,科技表!$1:$1048576,3,0) -> 科技树类型3 | Y21: 12016001 | Z21: =VLOOKUP($Y21,科技表!$1:$1048576,3,0) -> 科技树类型4 | AA21: 12016101 | AB21: =VLOOKUP($AA21,科技表!$1:$1048576,3,0) -> 科技树类型4 | AC21: 12017001 | AD21: =VLOOKUP($AC21,科技表!$1:$1048576,3,0) -> 科技树类型2 | AE21: 12017101 | AF21: =VLOOKUP($AE21,科技表!$1:$1048576,3,0) -> 科技树类型2 | AG21: 12021101 | AI21: 12022101 | AU21: 12010001
A22: 20000325 | B22: UITexture/Charactar/wangling/gho_base03 | C22: 1v1 | D22: 三本科技基地 | E22: 20000322 | G22: 12013201 | H22: =VLOOKUP($G22,科技表!$1:$1048576,3,0) -> 科技树类型1 | I22: 12014201 | J22: =VLOOKUP($I22,科技表!$1:$1048576,3,0) -> 科技树类型1 | K22: 12018001 | L22: =VLOOKUP($K22,科技表!$1:$1048576,3,0) -> 科技树类型2 | M22: 12018101 | N22: =VLOOKUP($M22,科技表!$1:$1048576,3,0) -> 科技树类型2 | O22: 12019001 | P22: =VLOOKUP($O22,科技表!$1:$1048576,3,0) -> 科技树类型4 | Q22: 12019101 | R22: =VLOOKUP($Q22,科技表!$1:$1048576,3,0) -> 科技树类型4 | S22: 12020001 | T22: =VLOOKUP($S22,科技表!$1:$1048576,3,0) -> 科技树类型3 | U22: 12020101 | V22: =VLOOKUP($U22,科技表!$1:$1048576,3,0) -> 科技树类型3 | W22: 12020201 | X22: =VLOOKUP($W22,科技表!$1:$1048576,3,0) -> 科技树类型3 | Y22: 12020301 | Z22: =VLOOKUP($Y22,科技表!$1:$1048576,3,0) -> 科技树类型3 | AA22: 12021201 | AC22: 12017201 | AD22: =VLOOKUP($AC22,科技表!$1:$1048576,3,0) -> 科技树类型2 | AE22: 12023101 | AG22: 12024101 | AI22: 12015011 | AJ22: =VLOOKUP($AI22,科技表!$1:$1048576,3,0) -> 科技树类型3 | AK22: 12022201
A23: 20000428 | B23: UITexture/Charactar/jingling/elf_base01 | C23: 1v1 | D23: 一本科技基地 | E23: 20000425 | F23: 13008001 | G23: 13011001 | H23: =VLOOKUP($G23,科技表!$1:$1048576,3,0) -> 科技树类型1 | I23: 13011101 | J23: =VLOOKUP($I23,科技表!$1:$1048576,3,0) -> 科技树类型1 | K23: 13011201 | L23: =VLOOKUP($K23,科技表!$1:$1048576,3,0) -> 科技树类型1 | M23: 13012001 | N23: =VLOOKUP($M23,科技表!$1:$1048576,3,0) -> 科技树类型1 | O23: 13006001 | Q23: 13022001 | S23: 13021001 | U23: 13023001 | AU23: 13009001 | AW23: 13003001 | AY23: 13004001 | BA23: 13005001
A24: 20000429 | B24: UITexture/Charactar/jingling/elf_base02 | C24: 1v1 | D24: 二本科技基地 | E24: 20000426 | G24: 13012101 | H24: =VLOOKUP($G24,科技表!$1:$1048576,3,0) -> 科技树类型1 | I24: 13013001 | J24: =VLOOKUP($I24,科技表!$1:$1048576,3,0) -> 科技树类型1 | K24: 13013101 | L24: =VLOOKUP($K24,科技表!$1:$1048576,3,0) -> 科技树类型1 | M24: 13014001 | N24: =VLOOKUP($M24,科技表!$1:$1048576,3,0) -> 科技树类型3 | O24: 13014101 | P24: =VLOOKUP($O24,科技表!$1:$1048576,3,0) -> 科技树类型3 | Q24: 13014201 | R24: =VLOOKUP($Q24,科技表!$1:$1048576,3,0) -> 科技树类型3 | S24: 13015001 | T24: =VLOOKUP($S24,科技表!$1:$1048576,3,0) -> 科技树类型3 | U24: 13015101 | V24: =VLOOKUP($U24,科技表!$1:$1048576,3,0) -> 科技树类型3 | W24: 13015201 | X24: =VLOOKUP($W24,科技表!$1:$1048576,3,0) -> 科技树类型3 | Y24: 13016001 | Z24: =VLOOKUP($Y24,科技表!$1:$1048576,3,0) -> 科技树类型4 | AA24: 13016101 | AB24: =VLOOKUP($AA24,科技表!$1:$1048576,3,0) -> 科技树类型4 | AC24: 13017001 | AD24: =VLOOKUP($AC24,科技表!$1:$1048576,3,0) -> 科技树类型1 | AE24: 13017101 | AF24: =VLOOKUP($AE24,科技表!$1:$1048576,3,0) -> 科技树类型1 | AG24: 13017201 | AH24: =VLOOKUP($AG24,科技表!$1:$1048576,3,0) -> 科技树类型1 | AI24: 13017301 | AJ24: =VLOOKUP($AI24,科技表!$1:$1048576,3,0) -> 科技树类型1 | AK24: 13018001 | AL24: =VLOOKUP($AK24,科技表!$1:$1048576,3,0) -> 科技树类型2 | AM24: 13018101 | AN24: =VLOOKUP($AM24,科技表!$1:$1048576,3,0) -> 科技树类型2 | AO24: 13021101 | AQ24: 13022101 | AU24: 13010001
A25: 20000430 | B25: UITexture/Charactar/jingling/elf_base03 | C25: 1v1 | D25: 三本科技基地 | E25: 20000427 | G25: 13013201 | H25: =VLOOKUP($G25,科技表!$1:$1048576,3,0) -> 科技树类型1 | I25: 13015301 | J25: =VLOOKUP($I25,科技表!$1:$1048576,3,0) -> 科技树类型3 | K25: 13019001 | L25: =VLOOKUP($K25,科技表!$1:$1048576,3,0) -> 科技树类型2 | M25: 13019101 | N25: =VLOOKUP($M25,科技表!$1:$1048576,3,0) -> 科技树类型2 | O25: 13019201 | P25: =VLOOKUP($O25,科技表!$1:$1048576,3,0) -> 科技树类型2 | Q25: 13020001 | R25: =VLOOKUP($Q25,科技表!$1:$1048576,3,0) -> 科技树类型4 | S25: 13020101 | T25: =VLOOKUP($S25,科技表!$1:$1048576,3,0) -> 科技树类型4 | U25: 13021201 | W25: 13022201
A26: 20000704 | B26: UITexture/Charactar/renlei/hum_base01 | C26: 新手1v1 | D26: 一本科技基地 | E26: 20000701 | F26: 17000001 | G26: 17011001 | H26: =VLOOKUP($G26,科技表!$1:$1048576,3,0) -> 科技树类型1 | I26: 17011101 | J26: =VLOOKUP($I26,科技表!$1:$1048576,3,0) -> 科技树类型1 | K26: 17012001 | L26: =VLOOKUP($K26,科技表!$1:$1048576,3,0) -> 科技树类型1 | M26: 17006001 | O26: 17022001 | Q26: 17021001 | AU26: 17001001 | AW26: 17003001 | AY26: 17004001 | BA26: 17005001
A27: 20000705 | B27: UITexture/Charactar/renlei/hum_base02 | C27: 新手1v1 | D27: 二本科技基地 | E27: 20000702 | G27: 17012101 | H27: =VLOOKUP($G27,科技表!$1:$1048576,3,0) -> 科技树类型1 | I27: 17013001 | J27: =VLOOKUP($I27,科技表!$1:$1048576,3,0) -> 科技树类型1 | K27: 17013101 | L27: =VLOOKUP($K27,科技表!$1:$1048576,3,0) -> 科技树类型1 | M27: 17014001 | N27: =VLOOKUP($M27,科技表!$1:$1048576,3,0) -> 科技树类型1 | O27: 17014101 | P27: =VLOOKUP($O27,科技表!$1:$1048576,3,0) -> 科技树类型1 | Q27: 17014201 | R27: =VLOOKUP($Q27,科技表!$1:$1048576,3,0) -> 科技树类型1 | S27: 17015001 | T27: =VLOOKUP($S27,科技表!$1:$1048576,3,0) -> 科技树类型2 | U27: 17015101 | V27: =VLOOKUP($U27,科技表!$1:$1048576,3,0) -> 科技树类型2 | W27: 17016001 | X27: =VLOOKUP($W27,科技表!$1:$1048576,3,0) -> 科技树类型3 | Y27: 17016101 | Z27: =VLOOKUP($Y27,科技表!$1:$1048576,3,0) -> 科技树类型3 | AA27: 17016201 | AB27: =VLOOKUP($AA27,科技表!$1:$1048576,3,0) -> 科技树类型3 | AC27: 17016301 | AD27: =VLOOKUP($AC27,科技表!$1:$1048576,3,0) -> 科技树类型3 | AE27: 17017001 | AF27: =VLOOKUP($AE27,科技表!$1:$1048576,3,0) -> 科技树类型4 | AG27: 17017101 | AH27: =VLOOKUP($AG27,科技表!$1:$1048576,3,0) -> 科技树类型4 | AI27: 17021101 | AK27: 10022101 | AU27: 17002001
A28: 20000706 | B28: UITexture/Charactar/renlei/hum_base03 | C28: 新手1v1 | D28: 三本科技基地 | E28: 20000703 | G28: 17013201 | H28: =VLOOKUP($G28,科技表!$1:$1048576,3,0) -> 科技树类型1 | I28: 17014301 | J28: =VLOOKUP($I28,科技表!$1:$1048576,3,0) -> 科技树类型1 | K28: 17018001 | L28: =VLOOKUP($K28,科技表!$1:$1048576,3,0) -> 科技树类型2 | M28: 17018101 | N28: =VLOOKUP($M28,科技表!$1:$1048576,3,0) -> 科技树类型2 | O28: 17019001 | P28: =VLOOKUP($O28,科技表!$1:$1048576,3,0) -> 科技树类型3 | Q28: 17019101 | R28: =VLOOKUP($Q28,科技表!$1:$1048576,3,0) -> 科技树类型3 | S28: 17020001 | T28: =VLOOKUP($S28,科技表!$1:$1048576,3,0) -> 科技树类型4 | U28: 17020101 | V28: =VLOOKUP($U28,科技表!$1:$1048576,3,0) -> 科技树类型4 | W28: 17021201 | Y28: 17022201
A29: 20000724 | B29: UITexture/Charactar/shouzu/orc_base01 | C29: 新手1v1 | D29: 一本科技基地 | E29: 20000721 | F29: 18000001 | G29: 18011001 | I29: 18012001 | K29: 18006001 | M29: 18022001 | O29: 18021001 | AU29: 18001001 | AW29: 18003001 | AY29: 18004001 | BA29: 18005001
A30: 20000725 | B30: UITexture/Charactar/shouzu/orc_base02 | C30: 新手1v1 | D30: 二本科技基地 | E30: 20000722 | G30: 18011101 | I30: 18012101 | K30: 18013001 | M30: 18013101 | O30: 18014001 | Q30: 18014101 | S30: 18015001 | U30: 18015101 | W30: 18015201 | Y30: 18016001 | AA30: 18016101 | AC30: 18017001 | AE30: 18017101 | AG30: 18018001 | AI30: 18021101 | AK30: 18022101 | AU30: 18002001
A31: 20000726 | B31: UITexture/Charactar/shouzu/orc_base03 | C31: 新手1v1 | D31: 三本科技基地 | E31: 20000723 | G31: 18013201 | I31: 18014201 | K31: 18015301 | M31: 18018101 | O31: 18019001 | Q31: 18019101 | S31: 18020001 | U31: 18020101 | W31: 18021201 | Y31: 18022201

Sheet 攻防科技效果
A1: 怪物ID | B1: 科技属性1效果 | C1: 科技属性1类型 | D1: 科技属性1数值 | E1: 科技属性2效果 | F1: 科技属性2类型 | G1: 科技属性2数值
A2: 20000101 | B2: 攻击力 | C2: 加成属性 | D2: 13 | E2: 护甲值 | F2: 加成属性 | G2: 72
A3: 20000102 | B3: 攻击力 | C3: 加成属性 | D3: 23 | E3: 护甲值 | F3: 加成属性 | G3: 72
A4: 20000103 | B4: 攻击力 | C4: 加成属性 | D4: 0 | E4: 护甲值 | F4: 加成属性 | G4: 0
A5: 20000104 | B5: 攻击力 | C5: 加成属性 | D5: 0 | E5: 护甲值 | F5: 加成属性 | G5: 0
A6: 20000105 | B6: 攻击力 | C6: 加成属性 | D6: 18 | E6: 护甲值 | F6: 加成属性 | G6: 72
A7: 20000106 | B7: 攻击力 | C7: 加成属性 | D7: 19 | E7: 护甲值 | F7: 加成属性 | G7: 72
A8: 20000107 | B8: 攻击力 | C8: 加成属性 | D8: 23 | E8: 护甲值 | F8: 加成属性 | G8: 72
A9: 20000108 | B9: 攻击力 | C9: 加成属性 | D9: 30 | E9: 护甲值 | F9: 加成属性 | G9: 72
A10: 20000109 | B10: 攻击力 | C10: 加成属性 | D10: 52 | E10: 护甲值 | F10: 加成属性 | G10: 72
A11: 20000110 | B11: 攻击力 | C11: 加成属性 | D11: 40 | E11: 护甲值 | F11: 加成属性 | G11: 72
A12: 20000201 | B12: 攻击力 | C12: 加成属性 | D12: 20 | E12: 护甲值 | F12: 加成属性 | G12: 72
A13: 20000202 | B13: 攻击力 | C13: 加成属性 | D13: 19 | E13: 护甲值 | F13: 加成属性 | G13: 72
... A61: 20000747 | B61: 攻击力 | C61: 加成属性 | D61: 0 | E61: 护甲值 | F61: 加成属性 | G61: 0

Sheet 推荐建造表
A1: ID | B1: 备注 | C1: 一本推荐兵种1 | D1: 一本推荐兵种2 | E1: 二本推荐兵种1 | F1: 二本推荐兵种2 | G1: 三本推荐兵种1 | H1: 三本推荐兵种2 | I1: 人口科技1场景ID | J1: 人口科技1科技ID | K1: 人口科技2场景ID | L1: 人口科技2科技ID | M1: 人口科技3场景ID | N1: 人口科技3科技ID | O1: 人口科技4场景ID | P1: 人口科技4科技ID | Q1: 人口科技5场景ID | R1: 人口科技5科技ID | S1: 人口科技6场景ID | T1: 人口科技6科技ID
A2: 1000 | B2: 人族新手出兵方案1 | C2: 20000707 | D2: 20000708 | E2: 20000708 | F2: 20000710 | G2: 20000716 | H2: 20000710 | I2: 2001 | J2: 17003001 | K2: 2002 | L2: 17003001 | M2: 2003 | N2: 17003001 | O2: 2004 | P2: 17003001
A3: 1001 | B3: 人族出兵方案1 | C3: 20000101 | D3: 20000102 | E3: 20000106 | F3: 20000105 | G3: 20000110 | H3: 20000108 | I3: 1002 | J3: 10003001 | K3: 1003 | L3: 10007001 | M3: 1004 | N3: 10007001 | O3: 1005 | P3: 10007001 | Q3: 1006 | R3: 10007001
A4: 1002 | B4: 人族出兵方案2 | C4: 20000101 | D4: 20000102 | E4: 20000106 | F4: 20000103 | G4: 20000108 | H4: 20000104 | I4: 1002 | J4: 10003001 | K4: 1003 | L4: 10007001 | M4: 1004 | N4: 10007001 | O4: 1005 | P4: 10007001 | Q4: 1006 | R4: 10007001
A5: 1101 | B5: 兽族出兵方案1 | C5: 20000201 | D5: 20000202 | E5: 20000206 | F5: 20000208 | G5: 20000210 | H5: 20000208 | I5: 1002 | J5: 11003001 | K5: 1003 | L5: 11007001 | M5: 1004 | N5: 11007001 | O5: 1005 | P5: 11007001 | Q5: 1006 | R5: 11007001
A6: 1102 | B6: 兽族出兵方案2 | C6: 20000201 | D6: 20000202 | E6: 20000206 | F6: 20000203 | G6: 20000210 | H6: 20000205 | I6: 1002 | J6: 11003001 | K6: 1003 | L6: 11007001 | M6: 1004 | N6: 11007001 | O6: 1005 | P6: 11007001 | Q6: 1006 | R6: 11007001
A7: 1201 | B7: 亡灵出兵方案1 | C7: 20000301 | D7: 20000302 | E7: 20000302 | F7: 20000306 | G7: 20000308 | H7: 20000309 | I7: 1002 | J7: 12003001 | K7: 1003 | L7: 12007001 | M7: 1004 | N7: 12007001 | O7: 1005 | P7: 12007001 | Q7: 1006 | R7: 12007001
A8: 1202 | B8: 亡灵出兵方案2 | C8: 20000301 | D8: 20000302 | E8: 20000304 | F8: 20000307 | G8: 20000310 | H8: 20000305 | I8: 1002 | J8: 12003001 | K8: 1003 | L8: 12007001 | M8: 1004 | N8: 12007001 | O8: 1005 | P8: 12007001 | Q8: 1006 | R8: 12007001
A9: 1301 | B9: 精灵出兵方案1 | C9: 20000402 | D9: 20000401 | E9: 20000405 | F9: 20000407 | G9: 20000409 | H9: 20000410 | I9: 1002 | J9: 13003001 | K9: 1003 | L9: 13007001 | M9: 1004 | N9: 13007001 | O9: 1005 | P9: 13007001 | Q9: 1006 | R9: 13007001
A10: 1302 | B10: 精灵出兵方案2 | C10: 20000402 | D10: 20000401 | E10: 20000403 | F10: 20000404 | G10: 20000406 | H10: 20000410 | I10: 1002 | J10: 13003001 | K10: 1003 | L10: 13007001 | M10: 1004 | N10: 13007001 | O10: 1005 | P10: 13007001 | Q10: 1006 | R10: 13007001

Sheet 科技表配表说明
A1: 科技ID | B1: 备注 | C1: 科技组 | D1: 科技等级 | E1: 种族 | F1: 科技类型 | G1: 科技子类型 | H1: 初始科技状态 | I1: 升级时间开销 | J1: 升级金币开销 | K1: 升级所需基地等级 | L1: 科技效果1类型 | M1: 科技效果1参数1 | N1: 科技效果1参数2 | O1: 科技效果1参数3 | P1: 科技效果1参数4 | Q1: 科技效果2类型 | R1: 科技效果2参数1 | S1: 科技效果2参数2 | T1: 科技效果2参数3 | U1: 科技效果2参数4 | V1: 科技图标 | W1: 描述
A2: 10001001 | C2: =LEFT(A2,6) -> 100010 | D2: 等级=数值 | E2: 0=中立种族 | F2: 0=单位科技 | G2: 0=科技子类型_NONE | H2: 0=科技状态_不可用 | I2: 时间=毫秒 | J2: 金币=数值 | K2: 等级=数值 | L2: 1=科技效果_解锁单位技能 | M2: 单位资源ID(怪物表) | N2: 技能栏位ID | V2: 图标路径 | W2: 城镇，可以升级至主城，升级后可解锁中级兵种和中级科技，提升基地等级可提高基地和副基地的战斗力。保护基地不被摧毁对获得战争的胜利至关重要！
A3: 100010为组ID，01为等级 | D3: 只有团队科技有科技等级，房子，攻防等 | E3: 1=人族 | F3: 1=团队科技 | G3: 1=单位基地升级科技 | H3: 1=科技状态_可研究 | L3: 2=科技效果_提升最大人口 | M3: 人口增加数目
A4: 100为人族科技组，010第一个科技 | E4: 2=兽族 | G4: 2=单位变身科技 | H4: 2=科技状态_研究中 | L4: 3=科技效果_提升单位攻防属性 | M4: 属性类型
A5: 110为兽族科技 | E5: 3=亡灵 | G5: 3=团队攻击升级科技 | H5: 3=科技状态_研究完成 | L5: 4=科技效果_基地科技升级 | M5: 技能升级资源ID（基地升级科技效果表ID）
A6: 120为亡灵科技 | E6: 4=精灵 | G6: 4=团队防御升级科技 | L6: 5=科技效果_孵化单位 | M6: 单位资源ID（怪物表） | N6: 数目
A7: 130为精灵科技 | G7: 5=团队人口升级科技 | L7: 6=科技效果_增加英雄技能 | M7: 技能ID
